Workbook
Name 불량: #REF!
Name 불량유형: #REF!
Name 생산이력: 표1[]
Name 제품: #REF!

Sheet 생산현황
A1: 2026년 5월생산이력
A2: 날짜 | B2: 설비 구분 | C2: G.S 구분 | D2: 설비명 | E2: 품번 | F2: 제품유형 | G2: C/V | H2: 판수 | I2: 불량수량 | J2: 실적수량 | K2: 작업자 | L2: 주/야 | M2: 시작 | N2: 종료 | O2: 작업시간 | P2: 비가동 시간 | Q2: 비가동 사유 | R2: 평균SHOT | S2: 일일판수 | T2: 단가 | U2: 생산금액(원) | V2: GRADE | W2: 1SHOT 중량 | X2: 총 사용량(g) | Y2: 원재료 비용(원) | Z2: 총 원재료 비용(원) | AA2: 비고(비가동 사유) | AB2: 공장구분
A3: 46145 | B3: PRESS | C3: S | D3: PS01-1 | E3: R600116 | F3: =VLOOKUP(표1[[#This Row],[품번]],[1]!품번구분[#Data],2,0) -> S | G3: 220 | H3: 55 | I3: 55 | J3: =표1[[#This Row],[C/V]]*표1[[#This Row],[판수]]-표1[[#This Row],[불량수량]] -> 12045 | K3: 티시우 | L3: 주간 | M3: 0.33333333 | N3: 0.75 | O3: =IF(M3-N3=0,0,ABS(IF(OR(L3="야간",L3="특야"),IF(N3>M3,(N3-M3)*1440,(N3+1-M3)*1440),(N3-M3)*1440))-IF($L3="연장",IF(AND([1]근무시간!$F$6>$M3,[1]근무시간!$G$6<$N3,[1]근무시간!$F$5<$M3),40,IF(AND([1]근무시간!$F$5>$M3,[1]근무시간!$G$6<$N3),100,IF(AND([1]근무시간!$F$5>$M3,[1]근무시간!$G$5<$N3,[1]근무시간!$G$6>$N3),60,0))),IF($L3="주간",IF(AND([1]근무시간!$F$10>$M3,[1]근무시간!$G$10<$N3),60,0),IF($L3="야간",IF($M3<[1]근무시간!$G$7,IF(AND([1]근무시간!$F$8>$M3,[1]근무시간!$G$8<$N3),60,0),IF(AND($M3>=[1]근무시간!$F$7,$N3<=[1]근무시간!$G$7,$N3<[1]근무시간!$G$14),IF([1]근무시간!$G$8<$N3,60,0),0)),IF($L3="특야",IF(AND($M3>[1]근무시간!#REF!,$M3<[1]근무시간!$F$12,$N3>[1]근무시간!$G$12),60,IF(AND(OR($M3>=[1]근무시간!$F$11,$M3<[1]근무시간!#REF!),$N3>[1]근무시간!$G$12),90,IF(AND(OR($M3>=[1]근무시간!$F$11,$M3<[1]근무시간!#REF!),$N3>[1]근무시간!#REF!),30,0))),0))))-IF(L3="비가동",IF(AND(WEEKDAY(A3)<>1,WEEKDAY(A3)<>7),IF(AND([1]근무시간!$F$6>$M3,[1]근무시간!$F$5<$M3,[1]근무시간!$G$6<$N3),40,IF(AND([1]근무시간!$F$5>$M3,[1]근무시간!$F$4<=$M3,[1]근무시간!$G$6<$N3),100,IF(AND([1]근무시간!$F$5>$M3,[1]근무시간!$F$4<=$M3,[1]근무시간!$G$5<$N3),60,IF(AND(OR([1]근무시간!$F$7<=$M3,[1]근무시간!$F$8>$M3),[1]근무시간!$G$8<IF($N3>=1,$N3-1,$N3),[1]근무시간!$G$7>=IF($N3>=1,$N3-1,$N3)),60,0)))),IF(OR(AND([1]근무시간!$F$10>$M3,[1]근무시간!$F$9<=$M3,[1]근무시간!$G$10<$N3),AND($M3>[1]근무시간!#REF!,$M3<[1]근무시간!$F$12,$N3>[1]근무시간!$G$12)),60,IF(AND(OR([1]근무시간!$F$11<=$M3,[1]근무시간!$F$12>IF($M3>1,$M3-1, $M3)),[1]근무시간!$G$12<IF($N3>=1,$N3-1,$N3)),90,IF(AND(OR([1]근무시간!$F$11<=$M3,[1]근무시간!#REF!>$M3),[1]근무시간!#REF!<IF($N3>1,$N3-1,$N3)),30,0)))),SUMIFS(O:O,$A:$A,A3,$D:$D,D3,$K:$K,K3,$L:$L,"비가동",$E:$E,E3))) -> 395 | P3: =IF(L3="비가동",0,SUMIFS(O:O,$A:$A,A3,$D:$D,D3,$K:$K,K3,$L:$L,"비가동",$E:$E,E3)) -> 145 | R3: =IF(H3=0,"",H3/O3*60) -> 8.3544304 | S3: =SUMIFS(H:H,$A:$A,A3,$D:$D,D3,$E:$E,E3) -> 163 | T3: =IF(L3="비가동",0,VLOOKUP(E3,[1]단가!$D$4:$G$1048576,4,0)) -> 36.72 | U3: =IF(L3="비가동",0,T3*J3) -> 442292.4 | V3: =IF($L3="비가동",0,IF($B3="in",VLOOKUP($E3,[1]투입량!$M:$T,3,FALSE),VLOOKUP($E3,[1]투입량!$D:$I,3,FALSE))) -> SI4022 | W3: =IF($L3="비가동",0,IF($B3="in",VLOOKUP($E3,[1]투입량!$M:$T,6,FALSE),VLOOKUP($E3,[1]투입량!$D:$I,5,FALSE))) -> 60 | X3: =IF(L3="비가동",0,(W3*1.1)*H3) -> 3630 | Y3: =IF(V3=0,0,VLOOKUP(V3,[1]원재료!C:H,3,0)*0.001) -> 10.15 | Z3: =Y3*X3 -> 36844.5 | AB3: 1공장
A4: 46145 | B4: PRESS | C4: S | D4: PS01-1 | E4: R600116 | F4: =VLOOKUP(표1[[#This Row],[품번]],[1]!품번구분[#Data],2,0) -> S | J4: =표1[[#This Row],[C/V]]*표1[[#This Row],[판수]]-표1[[#This Row],[불량수량]] -> 0 | K4: 티시우 | L4: 비가동 | M4: 0.33333333 | N4: 0.43402778 | O4: 145 | P4: 0 | Q4: 설비이상 | R4: =IF(H4=0,"",H4/O4*60) | S4: =SUMIFS(H:H,$A:$A,A4,$D:$D,D4,$E:$E,E4) -> 163 | T4: =IF(L4="비가동",0,VLOOKUP(E4,[1]단가!$D$4:$G$1048576,4,0)) -> 0 | U4: =IF(L4="비가동",0,T4*J4) -> 0 | V4: =IF($L4="비가동",0,IF($B4="in",VLOOKUP($E4,[1]투입량!$M:$T,3,FALSE),VLOOKUP($E4,[1]투입량!$D:$I,3,FALSE))) -> 0 | W4: =IF($L4="비가동",0,IF($B4="in",VLOOKUP($E4,[1]투입량!$M:$T,6,FALSE),VLOOKUP($E4,[1]투입량!$D:$I,5,FALSE))) -> 0 | X4: =IF(L4="비가동",0,(W4*1.1)*H4) -> 0 | Y4: =IF(V4=0,0,VLOOKUP(V4,[1]원재료!C:H,3,0)*0.001) -> 0 | Z4: =Y4*X4 -> 0 | AA4: 상히타 단선(3, 4번) | AB4: 1공장
A5: 46145 | B5: PRESS | C5: S | D5: PS01-2 | E5: R602252 | F5: =VLOOKUP(표1[[#This Row],[품번]],[1]!품번구분[#Data],2,0) -> S | G5: 190 | H5: 77 | I5: 77 | J5: =표1[[#This Row],[C/V]]*표1[[#This Row],[판수]]-표1[[#This Row],[불량수량]] -> 14553 | K5: 티시우 | L5: 주간 | M5: 0.33333333 | N5: 0.75 | O5: 540 | P5: 0 | R5: =IF(H5=0,"",H5/O5*60) -> 8.5555556 | S5: =SUMIFS(H:H,$A:$A,A5,$D:$D,D5,$E:$E,E5) -> 185 | T5: =IF(L5="비가동",0,VLOOKUP(E5,[1]단가!$D$4:$G$1048576,4,0)) -> 24 | U5: =IF(L5="비가동",0,T5*J5) -> 349272 | V5: =IF($L5="비가동",0,IF($B5="in",VLOOKUP($E5,[1]투입량!$M:$T,3,FALSE),VLOOKUP($E5,[1]투입량!$D:$I,3,FALSE))) -> SI3020 | W5: =IF($L5="비가동",0,IF($B5="in",VLOOKUP($E5,[1]투입량!$M:$T,6,FALSE),VLOOKUP($E5,[1]투입량!$D:$I,5,FALSE))) -> 208 | X5: =IF(L5="비가동",0,(W5*1.1)*H5) -> 17617.6 | Y5: =IF(V5=0,0,VLOOKUP(V5,[1]원재료!C:H,3,0)*0.001) -> 9.85 | Z5: =Y5*X5 -> 173533.36 | AB5: 1공장
A6: 46145 | B6: PRESS | C6: S | D6: PS01-3 | E6: NU 615470 | F6: =VLOOKUP(표1[[#This Row],[품번]],[1]!품번구분[#Data],2,0) -> G | G6: 90 | H6: 77 | J6: =표1[[#This Row],[C/V]]*표1[[#This Row],[판수]]-표1[[#This Row],[불량수량]] -> 6930 | K6: 티시우 | L6: 주간 | M6: 0.33333333 | N6: 0.75 | O6: 540 | P6: 0 | R6: =IF(H6=0,"",H6/O6*60) -> 8.5555556 | S6: =SUMIFS(H:H,$A:$A,A6,$D:$D,D6,$E:$E,E6) -> 185 | T6: =IF(L6="비가동",0,VLOOKUP(E6,[1]단가!$D$4:$G$1048576,4,0)) -> 60 | U6: =IF(L6="비가동",0,T6*J6) -> 415800 | V6: =IF($L6="비가동",0,IF($B6="in",VLOOKUP($E6,[1]투입량!$M:$T,3,FALSE),VLOOKUP($E6,[1]투입량!$D:$I,3,FALSE))) -> SI4027K | W6: =IF($L6="비가동",0,IF($B6="in",VLOOKUP($E6,[1]투입량!$M:$T,6,FALSE),VLOOKUP($E6,[1]투입량!$D:$I,5,FALSE))) -> 330 | X6: =IF(L6="비가동",0,(W6*1.1)*H6) -> 27951 | Y6: =IF(V6=0,0,VLOOKUP(V6,[1]원재료!C:H,3,0)*0.001) -> 9 | Z6: =Y6*X6 -> 251559 | AB6: 1공장
A7: 46145 | B7: PRESS | C7: S | D7: PS01-1 | E7: R600116 | F7: =VLOOKUP(표1[[#This Row],[품번]],[1]!품번구분[#Data],2,0) -> S | G7: 220 | H7: 108 | I7: 108 | J7: =표1[[#This Row],[C/V]]*표1[[#This Row],[판수]]-표1[[#This Row],[불량수량]] -> 23652 | K7: 티히엔(C) | L7: 특야 | M7: 0.75 | N7: 0.33333333 | O7: 750 | P7: 0 | R7: =IF(H7=0,"",H7/O7*60) -> 8.64 | S7: =SUMIFS(H:H,$A:$A,A7,$D:$D,D7,$E:$E,E7) -> 163 | T7: =IF(L7="비가동",0,VLOOKUP(E7,[1]단가!$D$4:$G$1048576,4,0)) -> 36.72 | U7: =IF(L7="비가동",0,T7*J7) -> 868501.44 | V7: =IF($L7="비가동",0,IF($B7="in",VLOOKUP($E7,[1]투입량!$M:$T,3,FALSE),VLOOKUP($E7,[1]투입량!$D:$I,3,FALSE))) -> SI4022 | W7: =IF($L7="비가동",0,IF($B7="in",VLOOKUP($E7,[1]투입량!$M:$T,6,FALSE),VLOOKUP($E7,[1]투입량!$D:$I,5,FALSE))) -> 60 | X7: =IF(L7="비가동",0,(W7*1.1)*H7) -> 7128 | Y7: =IF(V7=0,0,VLOOKUP(V7,[1]원재료!C:H,3,0)*0.001) -> 10.15 | Z7: =Y7*X7 -> 72349.2 | AB7: 1공장
A8: 46145 | B8: PRESS | C8: S | D8: PS01-2 | E8: R602252 | F8: =VLOOKUP(표1[[#This Row],[품번]],[1]!품번구분[#Data],2,0) -> S | G8: 190 | H8: 108 | I8: 108 | J8: =표1[[#This Row],[C/V]]*표1[[#This Row],[판수]]-표1[[#This Row],[불량수량]] -> 20412 | K8: 티히엔(C) | L8: 특야 | M8: 0.75 | N8: 0.33333333 | O8: 750 | P8: 0 | R8: =IF(H8=0,"",H8/O8*60) -> 8.64 | S8: =SUMIFS(H:H,$A:$A,A8,$D:$D,D8,$E:$E,E8) -> 185 | T8: =IF(L8="비가동",0,VLOOKUP(E8,[1]단가!$D$4:$G$1048576,4,0)) -> 24 | U8: =IF(L8="비가동",0,T8*J8) -> 489888 | V8: =IF($L8="비가동",0,IF($B8="in",VLOOKUP($E8,[1]투입량!$M:$T,3,FALSE),VLOOKUP($E8,[1]투입량!$D:$I,3,FALSE))) -> SI3020 | W8: =IF($L8="비가동",0,IF($B8="in",VLOOKUP($E8,[1]투입량!$M:$T,6,FALSE),VLOOKUP($E8,[1]투입량!$D:$I,5,FALSE))) -> 208 | X8: =IF(L8="비가동",0,(W8*1.1)*H8) -> 24710.4 | Y8: =IF(V8=0,0,VLOOKUP(V8,[1]원재료!C:H,3,0)*0.001) -> 9.85 | Z8: =Y8*X8 -> 243397.44 | AB8: 1공장
A9: 46145 | B9: PRESS | C9: S | D9: PS01-3 | E9: NU 615470 | F9: =VLOOKUP(표1[[#This Row],[품번]],[1]!품번구분[#Data],2,0) -> G | G9: 90 | H9: 108 | J9: =표1[[#This Row],[C/V]]*표1[[#This Row],[판수]]-표1[[#This Row],[불량수량]] -> 9720 | K9: 티히엔(C) | L9: 특야 | M9: 0.75 | N9: 0.33333333 | O9: 750 | P9: 0 | R9: =IF(H9=0,"",H9/O9*60) -> 8.64 | S9: =SUMIFS(H:H,$A:$A,A9,$D:$D,D9,$E:$E,E9) -> 185 | T9: =IF(L9="비가동",0,VLOOKUP(E9,[1]단가!$D$4:$G$1048576,4,0)) -> 60 | U9: =IF(L9="비가동",0,T9*J9) -> 583200 | V9: =IF($L9="비가동",0,IF($B9="in",VLOOKUP($E9,[1]투입량!$M:$T,3,FALSE),VLOOKUP($E9,[1]투입량!$D:$I,3,FALSE))) -> SI4027K | W9: =IF($L9="비가동",0,IF($B9="in",VLOOKUP($E9,[1]투입량!$M:$T,6,FALSE),VLOOKUP($E9,[1]투입량!$D:$I,5,FALSE))) -> 330 | X9: =IF(L9="비가동",0,(W9*1.1)*H9) -> 39204 | Y9: =IF(V9=0,0,VLOOKUP(V9,[1]원재료!C:H,3,0)*0.001) -> 9 | Z9: =Y9*X9 -> 352836 | AB9: 1공장
A10: 46145 | B10: PRESS | C10: S | D10: PS02-2 | E10: 230202 | F10: =VLOOKUP(표1[[#This Row],[품번]],[1]!품번구분[#Data],2,0) -> G | G10: 900 | H10: 32 | I10: 224 | J10: =표1[[#This Row],[C/V]]*표1[[#This Row],[판수]]-표1[[#This Row],[불량수량]] -> 28576 | K10: 반화 | L10: 특야 | M10: 0.75 | N10: 0.33333333 | O10: 610 | P10: 140 | R10: =IF(H10=0,"",H10/O10*60) -> 3.147541 | S10: =SUMIFS(H:H,$A:$A,A10,$D:$D,D10,$E:$E,E10) -> 32 | T10: =IF(L10="비가동",0,VLOOKUP(E10,[1]단가!$D$4:$G$1048576,4,0)) -> 100 | U10: =IF(L10="비가동",0,T10*J10) -> 2857600 | V10: =IF($L10="비가동",0,IF($B10="in",VLOOKUP($E10,[1]투입량!$M:$T,3,FALSE),VLOOKUP($E10,[1]투입량!$D:$I,3,FALSE))) -> Q4020 | W10: =IF($L10="비가동",0,IF($B10="in",VLOOKUP($E10,[1]투입량!$M:$T,6,FALSE),VLOOKUP($E10,[1]투입량!$D:$I,5,FALSE))) -> 60 | X10: =IF(L10="비가동",0,(W10*1.1)*H10) -> 2112 | Y10: =IF(V10=0,0,VLOOKUP(V10,[1]원재료!C:H,3,0)*0.001) -> 10.45 | Z10: =Y10*X10 -> 22070.4 | AB10: 1공장
A11: 46145 | B11: PRESS | C11: S | D11: PS02-2 | E11: 230202 | F11: =VLOOKUP(표1[[#This Row],[품번]],[1]!품번구분[#Data],2,0) -> G | J11: =표1[[#This Row],[C/V]]*표1[[#This Row],[판수]]-표1[[#This Row],[불량수량]] -> 0 | K11: 반화 | L11: 비가동 | M11: 0.75 | N11: 0.79166667 | O11: 60 | P11: 0 | Q11: 근태변경 | R11: =IF(H11=0,"",H11/O11*60) | S11: =SUMIFS(H:H,$A:$A,A11,$D:$D,D11,$E:$E,E11) -> 32 | T11: =IF(L11="비가동",0,VLOOKUP(E11,[1]단가!$D$4:$G$1048576,4,0)) -> 0 | U11: =IF(L11="비가동",0,T11*J11) -> 0 | V11: =IF($L11="비가동",0,IF($B11="in",VLOOKUP($E11,[1]투입량!$M:$T,3,FALSE),VLOOKUP($E11,[1]투입량!$D:$I,3,FALSE))) -> 0 | W11: =IF($L11="비가동",0,IF($B11="in",VLOOKUP($E11,[1]투입량!$M:$T,6,FALSE),VLOOKUP($E11,[1]투입량!$D:$I,5,FALSE))) -> 0 | X11: =IF(L11="비가동",0,(W11*1.1)*H11) -> 0 | Y11: =IF(V11=0,0,VLOOKUP(V11,[1]원재료!C:H,3,0)*0.001) -> 0 | Z11: =Y11*X11 -> 0 | AA11: 현장 관리 병행 | AB11: 1공장
A12: 46145 | B12: PRESS | C12: S | D12: PS02-2 | E12: 230202 | F12: =VLOOKUP(표1[[#This Row],[품번]],[1]!품번구분[#Data],2,0) -> G | J12: =표1[[#This Row],[C/V]]*표1[[#This Row],[판수]]-표1[[#This Row],[불량수량]] -> 0 | K12: 반화 | L12: 비가동 | M12: 0.27777778 | N12: 0.33333333 | O12: 80 | P12: 0 | Q12: 근태변경 | R12: =IF(H12=0,"",H12/O12*60) | S12: =SUMIFS(H:H,$A:$A,A12,$D:$D,D12,$E:$E,E12) -> 32 | T12: =IF(L12="비가동",0,VLOOKUP(E12,[1]단가!$D$4:$G$1048576,4,0)) -> 0 | U12: =IF(L12="비가동",0,T12*J12) -> 0 | V12: =IF($L12="비가동",0,IF($B12="in",VLOOKUP($E12,[1]투입량!$M:$T,3,FALSE),VLOOKUP($E12,[1]투입량!$D:$I,3,FALSE))) -> 0 | W12: =IF($L12="비가동",0,IF($B12="in",VLOOKUP($E12,[1]투입량!$M:$T,6,FALSE),VLOOKUP($E12,[1]투입량!$D:$I,5,FALSE))) -> 0 | X12: =IF(L12="비가동",0,(W12*1.1)*H12) -> 0 | Y12: =IF(V12=0,0,VLOOKUP(V12,[1]원재료!C:H,3,0)*0.001) -> 0 | Z12: =Y12*X12 -> 0 | AA12: 현장 관리 병행 | AB12: 1공장
A13: 46145 | B13: PRESS | C13: S | D13: PS03-1 | E13: R600050 | F13: =VLOOKUP(표1[[#This Row],[품번]],[1]!품번구분[#Data],2,0) -> S | G13: 252 | H13: 83 | J13: =표1[[#This Row],[C/V]]*표1[[#This Row],[판수]]-표1[[#This Row],[불량수량]] -> 20916 | K13: 응안 | L13: 주간 | M13: 0.33333333 | N13: 0.75 | O13: 540 | P13: 0 | R13: =IF(H13=0,"",H13/O13*60) -> 9.2222222 | S13: =SUMIFS(H:H,$A:$A,A13,$D:$D,D13,$E:$E,E13) -> 201 | T13: =IF(L13="비가동",0,VLOOKUP(E13,[1]단가!$D$4:$G$1048576,4,0)) -> 25.09 | U13: =IF(L13="비가동",0,T13*J13) -> 524782.44 | V13: =IF($L13="비가동",0,IF($B13="in",VLOOKUP($E13,[1]투입량!$M:$T,3,FALSE),VLOOKUP($E13,[1]투입량!$D:$I,3,FALSE))) -> SI4022 | W13: =IF($L13="비가동",0,IF($B13="in",VLOOKUP($E13,[1]투입량!$M:$T,6,FALSE),VLOOKUP($E13,[1]투입량!$D:$I,5,FALSE))) -> 354 | X13: =IF(L13="비가동",0,(W13*1.1)*H13) -> 32320.2 | Y13: =IF(V13=0,0,VLOOKUP(V13,[1]원재료!C:H,3,0)*0.001) -> 10.15 | Z13: =Y13*X13 -> 328050.03 | AB13: 1공장
A14: 46145 | B14: PRESS | C14: S | D14: PS03-2 | E14: R600063 | F14: =VLOOKUP(표1[[#This Row],[품번]],[1]!품번구분[#Data],2,0) -> S | G14: 170 | H14: 83 | I14: 83 | J14: =표1[[#This Row],[C/V]]*표1[[#This Row],[판수]]-표1[[#This Row],[불량수량]] -> 14027 | K14: 응안 | L14: 주간 | M14: 0.33333333 | N14: 0.75 | O14: 540 | P14: 0 | R14: =IF(H14=0,"",H14/O14*60) -> 9.2222222 | S14: =SUMIFS(H:H,$A:$A,A14,$D:$D,D14,$E:$E,E14) -> 201 | T14: =IF(L14="비가동",0,VLOOKUP(E14,[1]단가!$D$4:$G$1048576,4,0)) -> 19.73 | U14: =IF(L14="비가동",0,T14*J14) -> 276752.71 | V14: =IF($L14="비가동",0,IF($B14="in",VLOOKUP($E14,[1]투입량!$M:$T,3,FALSE),VLOOKUP($E14,[1]투입량!$D:$I,3,FALSE))) -> SI4022 | W14: =IF($L14="비가동",0,IF($B14="in",VLOOKUP($E14,[1]투입량!$M:$T,6,FALSE),VLOOKUP($E14,[1]투입량!$D:$I,5,FALSE))) -> 130 | X14: =IF(L14="비가동",0,(W14*1.1)*H14) -> 11869 | Y14: =IF(V14=0,0,VLOOKUP(V14,[1]원재료!C:H,3,0)*0.001) -> 10.15 | Z14: =Y14*X14 -> 120470.35 | AB14: 1공장
A15: 46145 | B15: PRESS | C15: S | D15: PS03-3 | E15: GL3 610853 | F15: =VLOOKUP(표1[[#This Row],[품번]],[1]!품번구분[#Data],2,0) -> G | G15: 160 | H15: 83 | J15: =표1[[#This Row],[C/V]]*표1[[#This Row],[판수]]-표1[[#This Row],[불량수량]] -> 13280 | K15: 응안 | L15: 주간 | M15: 0.33333333 | N15: 0.75 | O15: 540 | P15: 0 | R15: =IF(H15=0,"",H15/O15*60) -> 9.2222222 | S15: =SUMIFS(H:H,$A:$A,A15,$D:$D,D15,$E:$E,E15) -> 201 | T15: =IF(L15="비가동",0,VLOOKUP(E15,[1]단가!$D$4:$G$1048576,4,0)) -> 41 | U15: =IF(L15="비가동",0,T15*J15) -> 544480 | V15: =IF($L15="비가동",0,IF($B15="in",VLOOKUP($E15,[1]투입량!$M:$T,3,FALSE),VLOOKUP($E15,[1]투입량!$D:$I,3,FALSE))) -> Q4020 | W15: =IF($L15="비가동",0,IF($B15="in",VLOOKUP($E15,[1]투입량!$M:$T,6,FALSE),VLOOKUP($E15,[1]투입량!$D:$I,5,FALSE))) -> 200 | X15: =IF(L15="비가동",0,(W15*1.1)*H15) -> 18260 | Y15: =IF(V15=0,0,VLOOKUP(V15,[1]원재료!C:H,3,0)*0.001) -> 10.45 | Z15: =Y15*X15 -> 190817 | AB15: 1공장
A16: 46145 | B16: PRESS | C16: S | D16: PS03-1 | E16: R600050 | F16: =VLOOKUP(표1[[#This Row],[품번]],[1]!품번구분[#Data],2,0) -> S | G16: 252 | H16: 118 | J16: =표1[[#This Row],[C/V]]*표1[[#This Row],[판수]]-표1[[#This Row],[불량수량]] -> 29736 | K16: 튀린(B) | L16: 특야 | M16: 0.75 | N16: 0.33333333 | O16: 750 | P16: 0 | R16: =IF(H16=0,"",H16/O16*60) -> 9.44 | S16: =SUMIFS(H:H,$A:$A,A16,$D:$D,D16,$E:$E,E16) -> 201 | T16: =IF(L16="비가동",0,VLOOKUP(E16,[1]단가!$D$4:$G$1048576,4,0)) -> 25.09 | U16: =IF(L16="비가동",0,T16*J16) -> 746076.24 | V16: =IF($L16="비가동",0,IF($B16="in",VLOOKUP($E16,[1]투입량!$M:$T,3,FALSE),VLOOKUP($E16,[1]투입량!$D:$I,3,FALSE))) -> SI4022 | W16: =IF($L16="비가동",0,IF($B16="in",VLOOKUP($E16,[1]투입량!$M:$T,6,FALSE),VLOOKUP($E16,[1]투입량!$D:$I,5,FALSE))) -> 354 | X16: =IF(L16="비가동",0,(W16*1.1)*H16) -> 45949.2 | Y16: =IF(V16=0,0,VLOOKUP(V16,[1]원재료!C:H,3,0)*0.001) -> 10.15 | Z16: =Y16*X16 -> 466384.38 | AB16: 1공장
A17: 46145 | B17: PRESS | C17: S | D17: PS03-2 | E17: R600063 | F17: =VLOOKUP(표1[[#This Row],[품번]],[1]!품번구분[#Data],2,0) -> S | G17: 170 | H17: 118 | I17: 118 | J17: =표1[[#This Row],[C/V]]*표1[[#This Row],[판수]]-표1[[#This Row],[불량수량]] -> 19942 | K17: 튀린(B) | L17: 특야 | M17: 0.75 | N17: 0.33333333 | O17: 750 | P17: 0 | R17: =IF(H17=0,"",H17/O17*60) -> 9.44 | S17: =SUMIFS(H:H,$A:$A,A17,$D:$D,D17,$E:$E,E17) -> 201 | T17: =IF(L17="비가동",0,VLOOKUP(E17,[1]단가!$D$4:$G$1048576,4,0)) -> 19.73 | U17: =IF(L17="비가동",0,T17*J17) -> 393455.66 | V17: =IF($L17="비가동",0,IF($B17="in",VLOOKUP($E17,[1]투입량!$M:$T,3,FALSE),VLOOKUP($E17,[1]투입량!$D:$I,3,FALSE))) -> SI4022 | W17: =IF($L17="비가동",0,IF($B17="in",VLOOKUP($E17,[1]투입량!$M:$T,6,FALSE),VLOOKUP($E17,[1]투입량!$D:$I,5,FALSE))) -> 130 | X17: =IF(L17="비가동",0,(W17*1.1)*H17) -> 16874 | Y17: =IF(V17=0,0,VLOOKUP(V17,[1]원재료!C:H,3,0)*0.001) -> 10.15 | Z17: =Y17*X17 -> 171271.1 | AB17: 1공장
A18: 46145 | B18: PRESS | C18: S | D18: PS03-3 | E18: GL3 610853 | F18: =VLOOKUP(표1[[#This Row],[품번]],[1]!품번구분[#Data],2,0) -> G | G18: 160 | H18: 118 | J18: =표1[[#This Row],[C/V]]*표1[[#This Row],[판수]]-표1[[#This Row],[불량수량]] -> 18880 | K18: 튀린(B) | L18: 특야 | M18: 0.75 | N18: 0.33333333 | O18: 750 | P18: 0 | R18: =IF(H18=0,"",H18/O18*60) -> 9.44 | S18: =SUMIFS(H:H,$A:$A,A18,$D:$D,D18,$E:$E,E18) -> 201 | T18: =IF(L18="비가동",0,VLOOKUP(E18,[1]단가!$D$4:$G$1048576,4,0)) -> 41 | U18: =IF(L18="비가동",0,T18*J18) -> 774080 | V18: =IF($L18="비가동",0,IF($B18="in",VLOOKUP($E18,[1]투입량!$M:$T,3,FALSE),VLOOKUP($E18,[1]투입량!$D:$I,3,FALSE))) -> Q4020 | W18: =IF($L18="비가동",0,IF($B18="in",VLOOKUP($E18,[1]투입량!$M:$T,6,FALSE),VLOOKUP($E18,[1]투입량!$D:$I,5,FALSE))) -> 200 | X18: =IF(L18="비가동",0,(W18*1.1)*H18) -> 25960 | Y18: =IF(V18=0,0,VLOOKUP(V18,[1]원재료!C:H,3,0)*0.001) -> 10.45 | Z18: =Y18*X18 -> 271282 | AB18: 1공장
A19: 46145 | B19: PRESS | C19: S | D19: PS04-1 | E19: 681114 | F19: =VLOOKUP(표1[[#This Row],[품번]],[1]!품번구분[#Data],2,0) -> S | G19: 1156 | H19: 90 | I19: 270 | J19: =표1[[#This Row],[C/V]]*표1[[#This Row],[판수]]-표1[[#This Row],[불량수량]] -> 103770 | K19: 반록 | L19: 주간 | M19: 0.33333333 | N19: 0.75 | O19: 540 | P19: 0 | R19: =IF(H19=0,"",H19/O19*60) -> 10 | S19: =SUMIFS(H:H,$A:$A,A19,$D:$D,D19,$E:$E,E19) -> 220 | T19: =IF(L19="비가동",0,VLOOKUP(E19,[1]단가!$D$4:$G$1048576,4,0)) -> 8.76 | U19: =IF(L19="비가동",0,T19*J19) -> 909025.2 | V19: =IF($L19="비가동",0,IF($B19="in",VLOOKUP($E19,[1]투입량!$M:$T,3,FALSE),VLOOKUP($E19,[1]투입량!$D:$I,3,FALSE))) -> SI5521 | W19: =IF($L19="비가동",0,IF($B19="in",VLOOKUP($E19,[1]투입량!$M:$T,6,FALSE),VLOOKUP($E19,[1]투입량!$D:$I,5,FALSE))) -> 330 | X19: =IF(L19="비가동",0,(W19*1.1)*H19) -> 32670 | Y19: =IF(V19=0,0,VLOOKUP(V19,[1]원재료!C:H,3,0)*0.001) -> 8.25 | Z19: =Y19*X19 -> 269527.5 | AB19: 1공장
A20: 46145 | B20: PRESS | C20: S | D20: PS04-2 | E20: 410001 | F20: =VLOOKUP(표1[[#This Row],[품번]],[1]!품번구분[#Data],2,0) -> G | G20: 1600 | H20: 83 | J20: =표1[[#This Row],[C/V]]*표1[[#This Row],[판수]]-표1[[#This Row],[불량수량]] -> 132800 | K20: 단톤 | L20: 주간 | M20: 0.33333333 | N20: 0.75 | O20: 540 | P20: 0 | R20: =IF(H20=0,"",H20/O20*60) -> 9.2222222 | S20: =SUMIFS(H:H,$A:$A,A20,$D:$D,D20,$E:$E,E20) -> 202 | T20: =IF(L20="비가동",0,VLOOKUP(E20,[1]단가!$D$4:$G$1048576,4,0)) -> 9.5 | U20: =IF(L20="비가동",0,T20*J20) -> 1261600 | V20: =IF($L20="비가동",0,IF($B20="in",VLOOKUP($E20,[1]투입량!$M:$T,3,FALSE),VLOOKUP($E20,[1]투입량!$D:$I,3,FALSE))) -> Q4004-2 | W20: =IF($L20="비가동",0,IF($B20="in",VLOOKUP($E20,[1]투입량!$M:$T,6,FALSE),VLOOKUP($E20,[1]투입량!$D:$I,5,FALSE))) -> 46 | X20: =IF(L20="비가동",0,(W20*1.1)*H20) -> 4199.8 | Y20: =IF(V20=0,0,VLOOKUP(V20,[1]원재료!C:H,3,0)*0.001) -> 10.45 | Z20: =Y20*X20 -> 43887.91 | AB20: 1공장
A21: 46145 | B21: PRESS | C21: S | D21: PS04-1 | E21: 681114 | F21: =VLOOKUP(표1[[#This Row],[품번]],[1]!품번구분[#Data],2,0) -> S | G21: 1156 | H21: 130 | I21: 390 | J21: =표1[[#This Row],[C/V]]*표1[[#This Row],[판수]]-표1[[#This Row],[불량수량]] -> 149890 | K21: 마이(B) | L21: 특야 | M21: 0.75 | N21: 0.33333333 | O21: 750 | P21: 0 | R21: =IF(H21=0,"",H21/O21*60) -> 10.4 | S21: =SUMIFS(H:H,$A:$A,A21,$D:$D,D21,$E:$E,E21) -> 220 | T21: =IF(L21="비가동",0,VLOOKUP(E21,[1]단가!$D$4:$G$1048576,4,0)) -> 8.76 | U21: =IF(L21="비가동",0,T21*J21) -> 1313036.4 | V21: =IF($L21="비가동",0,IF($B21="in",VLOOKUP($E21,[1]투입량!$M:$T,3,FALSE),VLOOKUP($E21,[1]투입량!$D:$I,3,FALSE))) -> SI5521 | W21: =IF($L21="비가동",0,IF($B21="in",VLOOKUP($E21,[1]투입량!$M:$T,6,FALSE),VLOOKUP($E21,[1]투입량!$D:$I,5,FALSE))) -> 330 | X21: =IF(L21="비가동",0,(W21*1.1)*H21) -> 47190 | Y21: =IF(V21=0,0,VLOOKUP(V21,[1]원재료!C:H,3,0)*0.001) -> 8.25 | Z21: =Y21*X21 -> 389317.5 | AB21: 1공장
A22: 46145 | B22: PRESS | C22: S | D22: PS04-2 | E22: 410001 | F22: =VLOOKUP(표1[[#This Row],[품번]],[1]!품번구분[#Data],2,0) -> G | G22: 1600 | H22: 119 | J22: =표1[[#This Row],[C/V]]*표1[[#This Row],[판수]]-표1[[#This Row],[불량수량]] -> 190400 | K22: 홍공 | L22: 특야 | M22: 0.75 | N22: 0.33333333 | O22: 750 | P22: 0 | R22: =IF(H22=0,"",H22/O22*60) -> 9.52 | S22: =SUMIFS(H:H,$A:$A,A22,$D:$D,D22,$E:$E,E22) -> 202 | T22: =IF(L22="비가동",0,VLOOKUP(E22,[1]단가!$D$4:$G$1048576,4,0)) -> 9.5 | U22: =IF(L22="비가동",0,T22*J22) -> 1808800 | V22: =IF($L22="비가동",0,IF($B22="in",VLOOKUP($E22,[1]투입량!$M:$T,3,FALSE),VLOOKUP($E22,[1]투입량!$D:$I,3,FALSE))) -> Q4004-2 | W22: =IF($L22="비가동",0,IF($B22="in",VLOOKUP($E22,[1]투입량!$M:$T,6,FALSE),VLOOKUP($E22,[1]투입량!$D:$I,5,FALSE))) -> 46 | X22: =IF(L22="비가동",0,(W22*1.1)*H22) -> 6021.4 | Y22: =IF(V22=0,0,VLOOKUP(V22,[1]원재료!C:H,3,0)*0.001) -> 10.45 | Z22: =Y22*X22 -> 62923.63 | AB22: 1공장
A23: 46145 | B23: PRESS | C23: S | D23: PS05-1 | E23: 682622 | F23: =VLOOKUP(표1[[#This Row],[품번]],[1]!품번구분[#Data],2,0) -> S | G23: 1152 | H23: 80 | J23: =표1[[#This Row],[C/V]]*표1[[#This Row],[판수]]-표1[[#This Row],[불량수량]] -> 92160 | K23: 치그엉 | L23: 주간 | M23: 0.33333333 | N23: 0.75 | O23: 540 | P23: 0 | R23: =IF(H23=0,"",H23/O23*60) -> 8.8888889 | S23: =SUMIFS(H:H,$A:$A,A23,$D:$D,D23,$E:$E,E23) -> 200 | T23: =IF(L23="비가동",0,VLOOKUP(E23,[1]단가!$D$4:$G$1048576,4,0)) -> 7.47 | U23: =IF(L23="비가동",0,T23*J23) -> 688435.2 | V23: =IF($L23="비가동",0,IF($B23="in",VLOOKUP($E23,[1]투입량!$M:$T,3,FALSE),VLOOKUP($E23,[1]투입량!$D:$I,3,FALSE))) -> SI4021 | W23: =IF($L23="비가동",0,IF($B23="in",VLOOKUP($E23,[1]투입량!$M:$T,6,FALSE),VLOOKUP($E23,[1]투입량!$D:$I,5,FALSE))) -> 252 | X23: =IF(L23="비가동",0,(W23*1.1)*H23) -> 22176 | Y23: =IF(V23=0,0,VLOOKUP(V23,[1]원재료!C:H,3,0)*0.001) -> 8.8 | Z23: =Y23*X23 -> 195148.8 | AB23: 1공장
A24: 46145 | B24: PRESS | C24: S | D24: PS05-2 | E24: 430001 | F24: =VLOOKUP(표1[[#This Row],[품번]],[1]!품번구분[#Data],2,0) -> G | G24: 1600 | H24: 82 | J24: =표1[[#This Row],[C/V]]*표1[[#This Row],[판수]]-표1[[#This Row],[불량수량]] -> 131200 | K24: 티엔씨(C) | L24: 주간 | M24: 0.33333333 | N24: 0.75 | O24: 540 | P24: 0 | R24: =IF(H24=0,"",H24/O24*60) -> 9.1111111 | S24: =SUMIFS(H:H,$A:$A,A24,$D:$D,D24,$E:$E,E24) -> 197 | T24: =IF(L24="비가동",0,VLOOKUP(E24,[1]단가!$D$4:$G$1048576,4,0)) -> 15.5 | U24: =IF(L24="비가동",0,T24*J24) -> 2033600 | V24: =IF($L24="비가동",0,IF($B24="in",VLOOKUP($E24,[1]투입량!$M:$T,3,FALSE),VLOOKUP($E24,[1]투입량!$D:$I,3,FALSE))) -> Q4007 | W24: =IF($L24="비가동",0,IF($B24="in",VLOOKUP($E24,[1]투입량!$M:$T,6,FALSE),VLOOKUP($E24,[1]투입량!$D:$I,5,FALSE))) -> 76 | X24: =IF(L24="비가동",0,(W24*1.1)*H24) -> 6855.2 | Y24: =IF(V24=0,0,VLOOKUP(V24,[1]원재료!C:H,3,0)*0.001) -> 6.8 | Z24: =Y24*X24 -> 46615.36 | AB24: 1공장
A25: 46145 | B25: PRESS | C25: S | D25: PS05-1 | E25: 682622 | F25: =VLOOKUP(표1[[#This Row],[품번]],[1]!품번구분[#Data],2,0) -> S | G25: 1152 | H25: 120 | J25: =표1[[#This Row],[C/V]]*표1[[#This Row],[판수]]-표1[[#This Row],[불량수량]] -> 138240 | K25: 단민(B) | L25: 특야 | M25: 0.75 | N25: 0.33333333 | O25: 750 | P25: 0 | R25: =IF(H25=0,"",H25/O25*60) -> 9.6 | S25: =SUMIFS(H:H,$A:$A,A25,$D:$D,D25,$E:$E,E25) -> 200 | T25: =IF(L25="비가동",0,VLOOKUP(E25,[1]단가!$D$4:$G$1048576,4,0)) -> 7.47 | U25: =IF(L25="비가동",0,T25*J25) -> 1032652.8 | V25: =IF($L25="비가동",0,IF($B25="in",VLOOKUP($E25,[1]투입량!$M:$T,3,FALSE),VLOOKUP($E25,[1]투입량!$D:$I,3,FALSE))) -> SI4021 | W25: =IF($L25="비가동",0,IF($B25="in",VLOOKUP($E25,[1]투입량!$M:$T,6,FALSE),VLOOKUP($E25,[1]투입량!$D:$I,5,FALSE))) -> 252 | X25: =IF(L25="비가동",0,(W25*1.1)*H25) -> 33264 | Y25: =IF(V25=0,0,VLOOKUP(V25,[1]원재료!C:H,3,0)*0.001) -> 8.8 | Z25: =Y25*X25 -> 292723.2 | AB25: 1공장
A26: 46145 | B26: PRESS | C26: S | D26: PS05-2 | E26: 430001 | F26: =VLOOKUP(표1[[#This Row],[품번]],[1]!품번구분[#Data],2,0) -> G | G26: 1600 | H26: 115 | J26: =표1[[#This Row],[C/V]]*표1[[#This Row],[판수]]-표1[[#This Row],[불량수량]] -> 184000 | K26: 안득 | L26: 특야 | M26: 0.75 | N26: 0.33333333 | O26: 750 | P26: 0 | R26: =IF(H26=0,"",H26/O26*60) -> 9.2 | S26: =SUMIFS(H:H,$A:$A,A26,$D:$D,D26,$E:$E,E26) -> 197 | T26: =IF(L26="비가동",0,VLOOKUP(E26,[1]단가!$D$4:$G$1048576,4,0)) -> 15.5 | U26: =IF(L26="비가동",0,T26*J26) -> 2852000 | V26: =IF($L26="비가동",0,IF($B26="in",VLOOKUP($E26,[1]투입량!$M:$T,3,FALSE),VLOOKUP($E26,[1]투입량!$D:$I,3,FALSE))) -> Q4007 | W26: =IF($L26="비가동",0,IF($B26="in",VLOOKUP($E26,[1]투입량!$M:$T,6,FALSE),VLOOKUP($E26,[1]투입량!$D:$I,5,FALSE))) -> 76 | X26: =IF(L26="비가동",0,(W26*1.1)*H26) -> 9614 | Y26: =IF(V26=0,0,VLOOKUP(V26,[1]원재료!C:H,3,0)*0.001) -> 6.8 | Z26: =Y26*X26 -> 65375.2 | AB26: 1공장
A27: 46145 | B27: PRESS | C27: S | D27: PS06-1 | E27: R603626 | F27: =VLOOKUP(표1[[#This Row],[품번]],[1]!품번구분[#Data],2,0) -> S | G27: 80 | H27: 67 | J27: =표1[[#This Row],[C/V]]*표1[[#This Row],[판수]]-표1[[#This Row],[불량수량]] -> 5360 | K27: 중 | L27: 주간 | M27: 0.33333333 | N27: 0.75 | O27: 540 | P27: 0 | R27: =IF(H27=0,"",H27/O27*60) -> 7.4444444 | S27: =SUMIFS(H:H,$A:$A,A27,$D:$D,D27,$E:$E,E27) -> 163 | T27: =IF(L27="비가동",0,VLOOKUP(E27,[1]단가!$D$4:$G$1048576,4,0)) -> 150 | U27: =IF(L27="비가동",0,T27*J27) -> 804000 | V27: =IF($L27="비가동",0,IF($B27="in",VLOOKUP($E27,[1]투입량!$M:$T,3,FALSE),VLOOKUP($E27,[1]투입량!$D:$I,3,FALSE))) -> SI3020 | W27: =IF($L27="비가동",0,IF($B27="in",VLOOKUP($E27,[1]투입량!$M:$T,6,FALSE),VLOOKUP($E27,[1]투입량!$D:$I,5,FALSE))) -> 18 | X27: =IF(L27="비가동",0,(W27*1.1)*H27) -> 1326.6 | Y27: =IF(V27=0,0,VLOOKUP(V27,[1]원재료!C:H,3,0)*0.001) -> 9.85 | Z27: =Y27*X27 -> 13067.01 | AB27: 1공장
A28: 46145 | B28: PRESS | C28: S | D28: PS06-2 | E28: R600019 | F28: =VLOOKUP(표1[[#This Row],[품번]],[1]!품번구분[#Data],2,0) -> S | G28: 168 | H28: 67 | I28: 67 | J28: =표1[[#This Row],[C/V]]*표1[[#This Row],[판수]]-표1[[#This Row],[불량수량]] -> 11189 | K28: 중 | L28: 주간 | M28: 0.33333333 | N28: 0.75 | O28: 540 | P28: 0 | R28: =IF(H28=0,"",H28/O28*60) -> 7.4444444 | S28: =SUMIFS(H:H,$A:$A,A28,$D:$D,D28,$E:$E,E28) -> 163 | T28: =IF(L28="비가동",0,VLOOKUP(E28,[1]단가!$D$4:$G$1048576,4,0)) -> 12.74 | U28: =IF(L28="비가동",0,T28*J28) -> 142547.86 | V28: =IF($L28="비가동",0,IF($B28="in",VLOOKUP($E28,[1]투입량!$M:$T,3,FALSE),VLOOKUP($E28,[1]투입량!$D:$I,3,FALSE))) -> SI4022-2 | W28: =IF($L28="비가동",0,IF($B28="in",VLOOKUP($E28,[1]투입량!$M:$T,6,FALSE),VLOOKUP($E28,[1]투입량!$D:$I,5,FALSE))) -> 150 | X28: =IF(L28="비가동",0,(W28*1.1)*H28) -> 11055 | Y28: =IF(V28=0,0,VLOOKUP(V28,[1]원재료!C:H,3,0)*0.001) -> 8.75 | Z28: =Y28*X28 -> 96731.25 | AB28: 1공장
A29: 46145 | B29: PRESS | C29: S | D29: PS06-1 | E29: R603626 | F29: =VLOOKUP(표1[[#This Row],[품번]],[1]!품번구분[#Data],2,0) -> S | G29: 80 | H29: 96 | J29: =표1[[#This Row],[C/V]]*표1[[#This Row],[판수]]-표1[[#This Row],[불량수량]] -> 7680 | K29: 반탄(D) | L29: 특야 | M29: 0.75 | N29: 0.33333333 | O29: 750 | P29: 0 | R29: =IF(H29=0,"",H29/O29*60) -> 7.68 | S29: =SUMIFS(H:H,$A:$A,A29,$D:$D,D29,$E:$E,E29) -> 163 | T29: =IF(L29="비가동",0,VLOOKUP(E29,[1]단가!$D$4:$G$1048576,4,0)) -> 150 | U29: =IF(L29="비가동",0,T29*J29) -> 1152000 | V29: =IF($L29="비가동",0,IF($B29="in",VLOOKUP($E29,[1]투입량!$M:$T,3,FALSE),VLOOKUP($E29,[1]투입량!$D:$I,3,FALSE))) -> SI3020 | W29: =IF($L29="비가동",0,IF($B29="in",VLOOKUP($E29,[1]투입량!$M:$T,6,FALSE),VLOOKUP($E29,[1]투입량!$D:$I,5,FALSE))) -> 18 | X29: =IF(L29="비가동",0,(W29*1.1)*H29) -> 1900.8 | Y29: =IF(V29=0,0,VLOOKUP(V29,[1]원재료!C:H,3,0)*0.001) -> 9.85 | Z29: =Y29*X29 -> 18722.88 | AB29: 1공장
A30: 46145 | B30: PRESS | C30: S | D30: PS06-2 | E30: R600019 | F30: =VLOOKUP(표1[[#This Row],[품번]],[1]!품번구분[#Data],2,0) -> S | G30: 168 | H30: 96 | I30: 96 | J30: =표1[[#This Row],[C/V]]*표1[[#This Row],[판수]]-표1[[#This Row],[불량수량]] -> 16032 | K30: 반탄(D) | L30: 특야 | M30: 0.75 | N30: 0.33333333 | O30: 750 | P30: 0 | R30: =IF(H30=0,"",H30/O30*60) -> 7.68 | S30: =SUMIFS(H:H,$A:$A,A30,$D:$D,D30,$E:$E,E30) -> 163 | T30: =IF(L30="비가동",0,VLOOKUP(E30,[1]단가!$D$4:$G$1048576,4,0)) -> 12.74 | U30: =IF(L30="비가동",0,T30*J30) -> 204247.68 | V30: =IF($L30="비가동",0,IF($B30="in",VLOOKUP($E30,[1]투입량!$M:$T,3,FALSE),VLOOKUP($E30,[1]투입량!$D:$I,3,FALSE))) -> SI4022-2 | W30: =IF($L30="비가동",0,IF($B30="in",VLOOKUP($E30,[1]투입량!$M:$T,6,FALSE),VLOOKUP($E30,[1]투입량!$D:$I,5,FALSE))) -> 150 | X30: =IF(L30="비가동",0,(W30*1.1)*H30) -> 15840 | Y30: =IF(V30=0,0,VLOOKUP(V30,[1]원재료!C:H,3,0)*0.001) -> 8.75 | Z30: =Y30*X30 -> 138600 | AB30: 1공장
A31: 46145 | B31: PRESS | C31: S | D31: PS07-2 | E31: MQ4PG P4006 | F31: =VLOOKUP(표1[[#This Row],[품번]],[1]!품번구분[#Data],2,0) -> G | G31: 6 | H31: 80 | J31: =표1[[#This Row],[C/V]]*표1[[#This Row],[판수]]-표1[[#This Row],[불량수량]] -> 480 | K31: 부하이 | L31: 주간 | M31: 0.33333333 | N31: 0.75 | O31: 540 | P31: 0 | R31: =IF(H31=0,"",H31/O31*60) -> 8.8888889 | S31: =SUMIFS(H:H,$A:$A,A31,$D:$D,D31,$E:$E,E31) -> 192 | T31: =IF(L31="비가동",0,VLOOKUP(E31,[1]단가!$D$4:$G$1048576,4,0)) -> 700 | U31: =IF(L31="비가동",0,T31*J31) -> 336000 | V31: =IF($L31="비가동",0,IF($B31="in",VLOOKUP($E31,[1]투입량!$M:$T,3,FALSE),VLOOKUP($E31,[1]투입량!$D:$I,3,FALSE))) -> Q5009 | W31: =IF($L31="비가동",0,IF($B31="in",VLOOKUP($E31,[1]투입량!$M:$T,6,FALSE),VLOOKUP($E31,[1]투입량!$D:$I,5,FALSE))) -> 28 | X31: =IF(L31="비가동",0,(W31*1.1)*H31) -> 2464 | Y31: =IF(V31=0,0,VLOOKUP(V31,[1]원재료!C:H,3,0)*0.001) -> 8.14 | Z31: =Y31*X31 -> 20056.96 | AB31: 1공장
A32: 46145 | B32: PRESS | C32: S | D32: PS07-3 | E32: MQ4PG P4006 | F32: =VLOOKUP(표1[[#This Row],[품번]],[1]!품번구분[#Data],2,0) -> G | G32: 2 | H32: 80 | J32: =표1[[#This Row],[C/V]]*표1[[#This Row],[판수]]-표1[[#This Row],[불량수량]] -> 160 | K32: 부하이 | L32: 주간 | M32: 0.33333333 | N32: 0.75 | O32: 540 | P32: 0 | R32: =IF(H32=0,"",H32/O32*60) -> 8.8888889 | S32: =SUMIFS(H:H,$A:$A,A32,$D:$D,D32,$E:$E,E32) -> 192 | T32: =IF(L32="비가동",0,VLOOKUP(E32,[1]단가!$D$4:$G$1048576,4,0)) -> 700 | U32: =IF(L32="비가동",0,T32*J32) -> 112000 | V32: =IF($L32="비가동",0,IF($B32="in",VLOOKUP($E32,[1]투입량!$M:$T,3,FALSE),VLOOKUP($E32,[1]투입량!$D:$I,3,FALSE))) -> Q5009 | W32: =IF($L32="비가동",0,IF($B32="in",VLOOKUP($E32,[1]투입량!$M:$T,6,FALSE),VLOOKUP($E32,[1]투입량!$D:$I,5,FALSE))) -> 28 | X32: =IF(L32="비가동",0,(W32*1.1)*H32) -> 2464 | Y32: =IF(V32=0,0,VLOOKUP(V32,[1]원재료!C:H,3,0)*0.001) -> 8.14 | Z32: =Y32*X32 -> 20056.96 | AB32: 1공장
A33: 46145 | B33: PRESS | C33: S | D33: PS07-2 | E33: MQ4PG P4006 | F33: =VLOOKUP(표1[[#This Row],[품번]],[1]!품번구분[#Data],2,0) -> G | G33: 6 | H33: 112 | J33: =표1[[#This Row],[C/V]]*표1[[#This Row],[판수]]-표1[[#This Row],[불량수량]] -> 672 | K33: 반안(D) | L33: 특야 | M33: 0.75 | N33: 0.33333333 | O33: 750 | P33: 0 | R33: =IF(H33=0,"",H33/O33*60) -> 8.96 | S33: =SUMIFS(H:H,$A:$A,A33,$D:$D,D33,$E:$E,E33) -> 192 | T33: =IF(L33="비가동",0,VLOOKUP(E33,[1]단가!$D$4:$G$1048576,4,0)) -> 700 | U33: =IF(L33="비가동",0,T33*J33) -> 470400 | V33: =IF($L33="비가동",0,IF($B33="in",VLOOKUP($E33,[1]투입량!$M:$T,3,FALSE),VLOOKUP($E33,[1]투입량!$D:$I,3,FALSE))) -> Q5009 | W33: =IF($L33="비가동",0,IF($B33="in",VLOOKUP($E33,[1]투입량!$M:$T,6,FALSE),VLOOKUP($E33,[1]투입량!$D:$I,5,FALSE))) -> 28 | X33: =IF(L33="비가동",0,(W33*1.1)*H33) -> 3449.6 | Y33: =IF(V33=0,0,VLOOKUP(V33,[1]원재료!C:H,3,0)*0.001) -> 8.14 | Z33: =Y33*X33 -> 28079.744 | AB33: 1공장
A34: 46145 | B34: PRESS | C34: S | D34: PS07-3 | E34: MQ4PG P4006 | F34: =VLOOKUP(표1[[#This Row],[품번]],[1]!품번구분[#Data],2,0) -> G | G34: 2 | H34: 112 | J34: =표1[[#This Row],[C/V]]*표1[[#This Row],[판수]]-표1[[#This Row],[불량수량]] -> 224 | K34: 반안(D) | L34: 특야 | M34: 0.75 | N34: 0.33333333 | O34: 750 | P34: 0 | R34: =IF(H34=0,"",H34/O34*60) -> 8.96 | S34: =SUMIFS(H:H,$A:$A,A34,$D:$D,D34,$E:$E,E34) -> 192 | T34: =IF(L34="비가동",0,VLOOKUP(E34,[1]단가!$D$4:$G$1048576,4,0)) -> 700 | U34: =IF(L34="비가동",0,T34*J34) -> 156800 | V34: =IF($L34="비가동",0,IF($B34="in",VLOOKUP($E34,[1]투입량!$M:$T,3,FALSE),VLOOKUP($E34,[1]투입량!$D:$I,3,FALSE))) -> Q5009 | W34: =IF($L34="비가동",0,IF($B34="in",VLOOKUP($E34,[1]투입량!$M:$T,6,FALSE),VLOOKUP($E34,[1]투입량!$D:$I,5,FALSE))) -> 28 | X34: =IF(L34="비가동",0,(W34*1.1)*H34) -> 3449.6 | Y34: =IF(V34=0,0,VLOOKUP(V34,[1]원재료!C:H,3,0)*0.001) -> 8.14 | Z34: =Y34*X34 -> 28079.744 | AB34: 1공장
A35: 46145 | B35: PRESS | C35: S | D35: PS08-2 | E35: 680275 | F35: =VLOOKUP(표1[[#This Row],[품번]],[1]!품번구분[#Data],2,0) -> S | G35: 400 | H35: 75 | J35: =표1[[#This Row],[C/V]]*표1[[#This Row],[판수]]-표1[[#This Row],[불량수량]] -> 30000 | K35: 히우 | L35: 주간 | M35: 0.33333333 | N35: 0.75 | O35: 540 | P35: 0 | R35: =IF(H35=0,"",H35/O35*60) -> 8.3333333 | S35: =SUMIFS(H:H,$A:$A,A35,$D:$D,D35,$E:$E,E35) -> 180 | T35: =IF(L35="비가동",0,VLOOKUP(E35,[1]단가!$D$4:$G$1048576,4,0)) -> 10.58 | U35: =IF(L35="비가동",0,T35*J35) -> 317400 | V35: =IF($L35="비가동",0,IF($B35="in",VLOOKUP($E35,[1]투입량!$M:$T,3,FALSE),VLOOKUP($E35,[1]투입량!$D:$I,3,FALSE))) -> SI4021 | W35: =IF($L35="비가동",0,IF($B35="in",VLOOKUP($E35,[1]투입량!$M:$T,6,FALSE),VLOOKUP($E35,[1]투입량!$D:$I,5,FALSE))) -> 37 | X35: =IF(L35="비가동",0,(W35*1.1)*H35) -> 3052.5 | Y35: =IF(V35=0,0,VLOOKUP(V35,[1]원재료!C:H,3,0)*0.001) -> 8.8 | Z35: =Y35*X35 -> 26862 | AB35: 1공장
A36: 46145 | B36: PRESS | C36: S | D36: PS08-3 | E36: 682027 | F36: =VLOOKUP(표1[[#This Row],[품번]],[1]!품번구분[#Data],2,0) -> S | G36: 400 | H36: 75 | I36: 300 | J36: =표1[[#This Row],[C/V]]*표1[[#This Row],[판수]]-표1[[#This Row],[불량수량]] -> 29700 | K36: 히우 | L36: 주간 | M36: 0.33333333 | N36: 0.75 | O36: 540 | P36: 0 | R36: =IF(H36=0,"",H36/O36*60) -> 8.3333333 | S36: =SUMIFS(H:H,$A:$A,A36,$D:$D,D36,$E:$E,E36) -> 180 | T36: =IF(L36="비가동",0,VLOOKUP(E36,[1]단가!$D$4:$G$1048576,4,0)) -> 14.6 | U36: =IF(L36="비가동",0,T36*J36) -> 433620 | V36: =IF($L36="비가동",0,IF($B36="in",VLOOKUP($E36,[1]투입량!$M:$T,3,FALSE),VLOOKUP($E36,[1]투입량!$D:$I,3,FALSE))) -> SI4023 | W36: =IF($L36="비가동",0,IF($B36="in",VLOOKUP($E36,[1]투입량!$M:$T,6,FALSE),VLOOKUP($E36,[1]투입량!$D:$I,5,FALSE))) -> 240 | X36: =IF(L36="비가동",0,(W36*1.1)*H36) -> 19800 | Y36: =IF(V36=0,0,VLOOKUP(V36,[1]원재료!C:H,3,0)*0.001) -> 9.3 | Z36: =Y36*X36 -> 184140 | AB36: 1공장
A37: 46145 | B37: PRESS | C37: S | D37: PS08-2 | E37: 680275 | F37: =VLOOKUP(표1[[#This Row],[품번]],[1]!품번구분[#Data],2,0) -> S | G37: 400 | H37: 105 | J37: =표1[[#This Row],[C/V]]*표1[[#This Row],[판수]]-표1[[#This Row],[불량수량]] -> 42000 | K37: 이소명 | L37: 특야 | M37: 0.75 | N37: 0.33333333 | O37: 750 | P37: 0 | R37: =IF(H37=0,"",H37/O37*60) -> 8.4 | S37: =SUMIFS(H:H,$A:$A,A37,$D:$D,D37,$E:$E,E37) -> 180 | T37: =IF(L37="비가동",0,VLOOKUP(E37,[1]단가!$D$4:$G$1048576,4,0)) -> 10.58 | U37: =IF(L37="비가동",0,T37*J37) -> 444360 | V37: =IF($L37="비가동",0,IF($B37="in",VLOOKUP($E37,[1]투입량!$M:$T,3,FALSE),VLOOKUP($E37,[1]투입량!$D:$I,3,FALSE))) -> SI4021 | W37: =IF($L37="비가동",0,IF($B37="in",VLOOKUP($E37,[1]투입량!$M:$T,6,FALSE),VLOOKUP($E37,[1]투입량!$D:$I,5,FALSE))) -> 37 | X37: =IF(L37="비가동",0,(W37*1.1)*H37) -> 4273.5 | Y37: =IF(V37=0,0,VLOOKUP(V37,[1]원재료!C:H,3,0)*0.001) -> 8.8 | Z37: =Y37*X37 -> 37606.8 | AB37: 1공장
A38: 46145 | B38: PRESS | C38: S | D38: PS08-3 | E38: 682027 | F38: =VLOOKUP(표1[[#This Row],[품번]],[1]!품번구분[#Data],2,0) -> S | G38: 400 | H38: 105 | I38: 420 | J38: =표1[[#This Row],[C/V]]*표1[[#This Row],[판수]]-표1[[#This Row],[불량수량]] -> 41580 | K38: 이소명 | L38: 특야 | M38: 0.75 | N38: 0.33333333 | O38: 750 | P38: 0 | R38: =IF(H38=0,"",H38/O38*60) -> 8.4 | S38: =SUMIFS(H:H,$A:$A,A38,$D:$D,D38,$E:$E,E38) -> 180 | T38: =IF(L38="비가동",0,VLOOKUP(E38,[1]단가!$D$4:$G$1048576,4,0)) -> 14.6 | U38: =IF(L38="비가동",0,T38*J38) -> 607068 | V38: =IF($L38="비가동",0,IF($B38="in",VLOOKUP($E38,[1]투입량!$M:$T,3,FALSE),VLOOKUP($E38,[1]투입량!$D:$I,3,FALSE))) -> SI4023 | W38: =IF($L38="비가동",0,IF($B38="in",VLOOKUP($E38,[1]투입량!$M:$T,6,FALSE),VLOOKUP($E38,[1]투입량!$D:$I,5,FALSE))) -> 240 | X38: =IF(L38="비가동",0,(W38*1.1)*H38) -> 27720 | Y38: =IF(V38=0,0,VLOOKUP(V38,[1]원재료!C:H,3,0)*0.001) -> 9.3 | Z38: =Y38*X38 -> 257796 | AB38: 1공장
A39: 46145 | B39: PRESS | C39: S | D39: PS09-2 | E39: 681371 | F39: =VLOOKUP(표1[[#This Row],[품번]],[1]!품번구분[#Data],2,0) -> S | G39: 400 | H39: 86 | I39: 172 | J39: =표1[[#This Row],[C/V]]*표1[[#This Row],[판수]]-표1[[#This Row],[불량수량]] -> 34228 | K39: 반훙(B) | L39: 주간 | M39: 0.33333333 | N39: 0.75 | O39: 540 | P39: 0 | R39: =IF(H39=0,"",H39/O39*60) -> 9.5555556 | S39: =SUMIFS(H:H,$A:$A,A39,$D:$D,D39,$E:$E,E39) -> 211 | T39: =IF(L39="비가동",0,VLOOKUP(E39,[1]단가!$D$4:$G$1048576,4,0)) -> 11.89 | U39: =IF(L39="비가동",0,T39*J39) -> 406970.92 | V39: =IF($L39="비가동",0,IF($B39="in",VLOOKUP($E39,[1]투입량!$M:$T,3,FALSE),VLOOKUP($E39,[1]투입량!$D:$I,3,FALSE))) -> SI4023 | W39: =IF($L39="비가동",0,IF($B39="in",VLOOKUP($E39,[1]투입량!$M:$T,6,FALSE),VLOOKUP($E39,[1]투입량!$D:$I,5,FALSE))) -> 169.5 | X39: =IF(L39="비가동",0,(W39*1.1)*H39) -> 16034.7 | Y39: =IF(V39=0,0,VLOOKUP(V39,[1]원재료!C:H,3,0)*0.001) -> 9.3 | Z39: =Y39*X39 -> 149122.71 | AB39: 1공장
A40: 46145 | B40: PRESS | C40: S | D40: PS09-3 | E40: 680772 | F40: =VLOOKUP(표1[[#This Row],[품번]],[1]!품번구분[#Data],2,0) -> S | G40: 324 | H40: 86 | I40: 86 | J40: =표1[[#This Row],[C/V]]*표1[[#This Row],[판수]]-표1[[#This Row],[불량수량]] -> 27778 | K40: 반훙(B) | L40: 주간 | M40: 0.33333333 | N40: 0.75 | O40: 540 | P40: 0 | R40: =IF(H40=0,"",H40/O40*60) -> 9.5555556 | S40: =SUMIFS(H:H,$A:$A,A40,$D:$D,D40,$E:$E,E40) -> 211 | T40: =IF(L40="비가동",0,VLOOKUP(E40,[1]단가!$D$4:$G$1048576,4,0)) -> 8.94 | U40: =IF(L40="비가동",0,T40*J40) -> 248335.32 | V40: =IF($L40="비가동",0,IF($B40="in",VLOOKUP($E40,[1]투입량!$M:$T,3,FALSE),VLOOKUP($E40,[1]투입량!$D:$I,3,FALSE))) -> SI4020 | W40: =IF($L40="비가동",0,IF($B40="in",VLOOKUP($E40,[1]투입량!$M:$T,6,FALSE),VLOOKUP($E40,[1]투입량!$D:$I,5,FALSE))) -> 88 | X40: =IF(L40="비가동",0,(W40*1.1)*H40) -> 8324.8 | Y40: =IF(V40=0,0,VLOOKUP(V40,[1]원재료!C:H,3,0)*0.001) -> 8.7 | Z40: =Y40*X40 -> 72425.76 | AB40: 1공장
...
